<?xml version="1.0" encoding="UTF-8"?>
<!-- Generated by org.testng.reporters.JUnitReportReporter -->
<testsuite skipped="0" hostname="DESKTOP-SC9RK3H" name="com.training.regression.tests.CYTC_065ProvideAccessToMultipleUsersTest" tests="4" failures="0" timestamp="04 Mar 2019 16:47:07 GMT" time="52.423" errors="1">
  <testcase name="ProvideAccessToUsers" time="31.207" classname="com.training.regression.tests.CYTC_065ProvideAccessToMultipleUsersTest">
    <error type="org.testng.internal.reflect.MethodMatcherException" message="
Data provider mismatch
Method: ProvideAccessToUsers([Parameter{index=0, type=java.lang.String, declaredAnnotations=[]}])
Arguments: [null,null]">
      <![CDATA[org.testng.internal.reflect.MethodMatcherException: 
Data provider mismatch
Method: ProvideAccessToUsers([Parameter{index=0, type=java.lang.String, declaredAnnotations=[]}])
Arguments: [null,null]
at org.testng.internal.reflect.DataProviderMethodMatcher.getConformingArguments(DataProviderMethodMatcher.java:45)
at org.testng.internal.Parameters.injectParameters(Parameters.java:796)
at org.testng.internal.Invoker.invokeTestMethods(Invoker.java:982)
at org.testng.internal.TestMethodWorker.invokeTestMethods(TestMethodWorker.java:125)
at org.testng.internal.TestMethodWorker.run(TestMethodWorker.java:109)
at org.testng.TestRunner.privateRun(TestRunner.java:648)
at org.testng.TestRunner.run(TestRunner.java:505)
at org.testng.SuiteRunner.runTest(SuiteRunner.java:455)
at org.testng.SuiteRunner.runSequentially(SuiteRunner.java:450)
at org.testng.SuiteRunner.privateRun(SuiteRunner.java:415)
at org.testng.SuiteRunner.run(SuiteRunner.java:364)
at org.testng.SuiteRunnerWorker.runSuite(SuiteRunnerWorker.java:52)
at org.testng.SuiteRunnerWorker.run(SuiteRunnerWorker.java:84)
at org.testng.TestNG.runSuitesSequentially(TestNG.java:1208)
at org.testng.TestNG.runSuitesLocally(TestNG.java:1137)
at org.testng.TestNG.runSuites(TestNG.java:1049)
at org.testng.TestNG.run(TestNG.java:1017)
at org.testng.remote.AbstractRemoteTestNG.run(AbstractRemoteTestNG.java:114)
at org.testng.remote.RemoteTestNG.initAndRun(RemoteTestNG.java:251)
at org.testng.remote.RemoteTestNG.main(RemoteTestNG.java:77)
]]>
    </error>
  </testcase> <!-- ProvideAccessToUsers -->
  <testcase name="ProvideAccessToUsers" time="9.237" classname="com.training.regression.tests.CYTC_065ProvideAccessToMultipleUsersTest"/>
  <testcase name="ProvideAccessToUsers" time="8.084" classname="com.training.regression.tests.CYTC_065ProvideAccessToMultipleUsersTest"/>
  <testcase name="ProvideAccessToUsers" time="3.895" classname="com.training.regression.tests.CYTC_065ProvideAccessToMultipleUsersTest"/>
</testsuite> <!-- com.training.regression.tests.CYTC_065ProvideAccessToMultipleUsersTest -->
